Workbook

Sheet 학술지정보
C2: Updated : | D2: 2025.01.22
C3: 학술지판정 및 IF, ES 산출기준 : | D3: JCR 기준 / | E3: 2023 | F3: 년도
C4: JCR link : | D4: https://jcr.clarivate.com/JCRLandingPageAction.action
C5: 보정 IF, 보정 ES link : | D5: http://bkplus.nrf.re.kr/bkms
C6: 산정기준 : | D6: 1) JIF Percentile이 높을수록, 2) Category에서 더 높은 rating으로 선정
C7: 1 | D7: 2 | E7: 3 | F7: 4 | G7: 5 | H7: 6 | I7: 7 | J7: 8 | K7: 9 | L7: 10 | M7: 11 | N7: 12 | O7: 13
A8: Scopus 등재 여부 | B8: 번호 | C8: 학술지명 | D8: 논문구분 | E8: ISSN | F8: ISBN | G8: e-ISSN | H8: Categories | I8: N of Rank | J8: R of Rank | K8: JIF Percentile(%) | L8: Top xx% | M8: Rating | N8: IF | O8: ES | Q8: No. | R8: Categories | S8: # of Journal : | T8: 20% of Journal :
A9: ㅇ | B9: 1 | C9: Bulletin of Earthquake Engineering | D9: SCI(E) | E9: 1570-761X | G9: 1573-1456 | H9: Geosciences, Multidisciplinary | I9: =INDEX($R$9:$T$20,MATCH($H9,$R$9:$R$20,0),2) -> 254 | J9: 50 | K9: 80.5 | L9: =100-K9 -> 19.5 | M9: =IF(L9<25,"Q1",IF(L9<50,"Q2",IF(L9<75,"Q3","Q4"))) -> Q1 | N9: =2040/539 -> 3.7847866 | O9: 0.00883 | Q9: 1 | R9: Engineering, Geological | S9: 63 | T9: =ROUNDDOWN(S9*0.2,0) -> 12
A10: ㅇ | B10: =B9+1 -> 2 | C10: Soil Dynamics and Earthquake Engineering | D10: SCI(E) | E10: 0267-7261 | G10: 1879-341X | H10: Geosciences, Multidisciplinary | I10: =INDEX($R$9:$T$20,MATCH($H10,$R$9:$R$20,0),2) -> 254 | J10: 34 | K10: 86.8 | L10: =100-K10 -> 13.2 | M10: =IF(L10<25,"Q1",IF(L10<50,"Q2",IF(L10<75,"Q3","Q4"))) -> Q1 | N10: =4534/1085 -> 4.1788018 | O10: 0.01773 | Q10: 2 | R10: Engineering, Civil | S10: 182 | T10: =ROUNDDOWN(S10*0.2,0) -> 36
A11: ㅇ | B11: =B10+1 -> 3 | C11: Ocean Engineering | D11: SCI(E) | E11: 0029-8018 | G11: 1873-5258 | H11: Oceanography | I11: =INDEX($R$9:$T$20,MATCH($H11,$R$9:$R$20,0),2) -> 65 | J11: 4 | K11: 94.6 | L11: =100-K11 -> 5.4 | M11: =IF(L11<25,"Q1",IF(L11<50,"Q2",IF(L11<75,"Q3","Q4"))) -> Q1 | N11: =19648/4309 -> 4.5597586 | O11: 0.04254 | Q11: 3 | R11: Geochemistry & Geophysics | S11: 101 | T11: =ROUNDDOWN(S11*0.2,0) -> 20
A12: ㅇ | B12: =B11+1 -> 4 | C12: Tunnelling and Underground Space Technology | D12: SCI(E) | E12: 0886-7798 | G12: 1878-4364 | H12: Engineering, Civil | I12: =INDEX($R$9:$T$20,MATCH($H12,$R$9:$R$20,0),2) -> 182 | J12: 9 | K12: 95.3 | L12: =100-K12 -> 4.7 | M12: =IF(L12<25,"Q1",IF(L12<50,"Q2",IF(L12<75,"Q3","Q4"))) -> Q1 | N12: =6898/1036 -> 6.6583012 | O12: 0.02221 | Q12: 4 | R12: Physics, Applied | S12: 148 | T12: =ROUNDDOWN(S12*0.2,0) -> 29
A13: ㅇ | B13: =B12+1 -> 5 | C13: Bulletin of the Seismological Society of America | D13: SCI(E) | E13: 0037-1106 | G13: 1943-3573 | H13: Geochemistry & Geophysics | I13: =INDEX($R$9:$T$20,MATCH($H13,$R$9:$R$20,0),2) -> 101 | J13: 35 | K13: 65.8 | L13: =100-K13 -> 34.2 | M13: =IF(L13<25,"Q1",IF(L13<50,"Q2",IF(L13<75,"Q3","Q4"))) -> Q2 | N13: =1020/385 -> 2.6493506 | O13: 0.00845 | Q13: 5 | R13: Engineering, Ocean | S13: 14 | T13: =ROUNDDOWN(S13*0.2,0) -> 2
A14: ㅇ | B14: =B13+1 -> 6 | C14: Rock Mechanics and Rock Engineering | D14: SCI(E) | E14: 0723-2632 | G14: 1434-453X | H14: Geosciences, Multidisciplinary | I14: =INDEX($R$9:$T$20,MATCH($H14,$R$9:$R$20,0),2) -> 254 | J14: 23 | K14: 91.1 | L14: =100-K14 -> 8.9 | M14: =IF(L14<25,"Q1",IF(L14<50,"Q2",IF(L14<75,"Q3","Q4"))) -> Q1 | N14: =4647/850 -> 5.4670588 | O14: 0.01961 | Q14: 6 | R14: Geosciences, Multidisciplinary | S14: 254 | T14: =ROUNDDOWN(S14*0.2,0) -> 50
A15: ㅇ | B15: =B14+1 -> 7 | C15: Journal of Geotechnical and Geoenvironmental Engineering | D15: SCI(E) | E15: 1090-0241 | G15: 1943-5606 | H15: Geosciences, Multidisciplinary | I15: =INDEX($R$9:$T$20,MATCH($H15,$R$9:$R$20,0),2) -> 254 | J15: 45 | K15: 82.5 | L15: =100-K15 -> 17.5 | M15: =IF(L15<25,"Q1",IF(L15<50,"Q2",IF(L15<75,"Q3","Q4"))) -> Q1 | N15: =1629/418 -> 3.8971292 | O15: 0.00834 | Q15: 7 | R15: Oceanography | S15: 65 | T15: =ROUNDDOWN(S15*0.2,0) -> 13
A16: ㅇ | B16: =B15+1 -> 8 | C16: Applied Sciences-Basel | D16: SCI(E) | E16: - | G16: 2076-3417 | H16: Engineering, Multidisciplinary | I16: =INDEX($R$9:$T$20,MATCH($H16,$R$9:$R$20,0),2) -> 181 | J16: 44 | K16: 76 | L16: =100-K16 -> 24 | M16: =IF(L16<25,"Q1",IF(L16<50,"Q2",IF(L16<75,"Q3","Q4"))) -> Q1 | N16: =60716/24763 -> 2.4518839 | O16: 0.11103 | Q16: 8 | R16: Construction & Building Technology | S16: 92 | T16: =ROUNDDOWN(S16*0.2,0) -> 18
A17: ㅇ | B17: =B16+1 -> 9 | C17: KSCE Journal of Civil Engineering | D17: SCI(E) | E17: 1226-7988 | G17: 1976-3808 | H17: Engineering, Civil | I17: =INDEX($R$9:$T$20,MATCH($H17,$R$9:$R$20,0),2) -> 182 | J17: 91 | K17: 50.3 | L17: =100-K17 -> 49.7 | M17: =IF(L17<25,"Q1",IF(L17<50,"Q2",IF(L17<75,"Q3","Q4"))) -> Q2 | N17: =1601/838 -> 1.9105012 | O17: 0.00712 | Q17: 9 | R17: Engineering, Multidisciplinary | S17: 181 | T17: =ROUNDDOWN(S17*0.2,0) -> 36
A18: ㅇ | B18: =B17+1 -> 10 | C18: Engineering Structures | D18: SCI(E) | E18: 0141-0296 | G18: 1873-7323 | H18: Engineering, Civil | I18: =INDEX($R$9:$T$20,MATCH($H18,$R$9:$R$20,0),2) -> 182 | J18: 18 | K18: 90.4 | L18: =100-K18 -> 9.6 | M18: =IF(L18<25,"Q1",IF(L18<50,"Q2",IF(L18<75,"Q3","Q4"))) -> Q1 | N18: =19364/3484 -> 5.5579793 | O18: 0.05699 | Q18: 10 | R18: Engineering, Mechanical | S18: 183 | T18: =ROUNDDOWN(S18*0.2,0) -> 36
A19: ㅇ | B19: =B18+1 -> 11 | C19: Geomechanics and Engineering | D19: SCI(E) | E19: 2005-307X | G19: 2092-6219 | H19: Engineering, Civil | I19: =INDEX($R$9:$T$20,MATCH($H19,$R$9:$R$20,0),2) -> 182 | J19: 70 | K19: 61.8 | L19: =100-K19 -> 38.2 | M19: =IF(L19<25,"Q1",IF(L19<50,"Q2",IF(L19<75,"Q3","Q4"))) -> Q2 | N19: =961/390 -> 2.4641026 | O19: 0.00277 | Q19: 11 | R19: GEOGRAPHY, PHYSICAL | S19: 50 | T19: =ROUNDDOWN(S19*0.2,0) -> 10
A20: ㅇ | B20: =B19+1 -> 12 | C20: Engineering Computations | D20: SCI(E) | E20: 0264-4401 | G20: 1758-7077 | H20: Engineering, Multidisciplinary | I20: =INDEX($R$9:$T$20,MATCH($H20,$R$9:$R$20,0),2) -> 181 | J20: 75 | K20: 58.8 | L20: =100-K20 -> 41.2 | M20: =IF(L20<25,"Q1",IF(L20<50,"Q2",IF(L20<75,"Q3","Q4"))) -> Q2 | N20: =321/215 -> 1.4930233 | O20: 0.00182 | Q20: 12 | R20: CONSTRUCTION & BUILDING TECHNOLOGY | S20: 92 | T20: =ROUNDDOWN(S20*0.2,0) -> 18
A21: ㅇ | B21: =B20+1 -> 13 | C21: Earthquake Spectra | D21: SCI(E) | E21: 8755-2930 | G21: 1944-8201 | H21: Engineering, Civil | I21: =INDEX($R$9:$T$20,MATCH($H21,$R$9:$R$20,0),2) -> 182 | J21: 51 | K21: 72.3 | L21: =100-K21 -> 27.7 | M21: =IF(L21<25,"Q1",IF(L21<50,"Q2",IF(L21<75,"Q3","Q4"))) -> Q2 | N21: =754/240 -> 3.1416667 | O21: 0.00389
A22: ㅇ | B22: =B21+1 -> 14 | C22: Earthquake Engineering & Structural Dynamics | D22: SCI(E) | E22: 0098-8847 | G22: 1096-9845 | H22: Engineering, Civil | I22: =INDEX($R$9:$T$20,MATCH($H22,$R$9:$R$20,0),2) -> 182 | J22: 26 | K22: 86 | L22: =100-K22 -> 14 | M22: =IF(L22<25,"Q1",IF(L22<50,"Q2",IF(L22<75,"Q3","Q4"))) -> Q1 | N22: =1526/358 -> 4.2625698 | O22: 0.00601
A23: ㅇ | B23: =B22+1 -> 15 | C23: Transportation Geotechnics | D23: SCI(E) | E23: 2214-3912 | G23: 2214-3912 | H23: Engineering, Civil | I23: =INDEX($R$9:$T$20,MATCH($H23,$R$9:$R$20,0),2) -> 182 | J23: 20 | K23: 89.3 | L23: =100-K23 -> 10.7 | M23: =IF(L23<25,"Q1",IF(L23<50,"Q2",IF(L23<75,"Q3","Q4"))) -> Q1 | N23: =2345/479 -> 4.8956159 | O23: 0.00569
A24: ㅇ | B24: =B23+1 -> 16 | C24: Journal of Earthquake Engineering | D24: SCI(E) | E24: 1363-2469 | G24: 1559-808X | H24: Engineering, Civil | I24: =INDEX($R$9:$T$20,MATCH($H24,$R$9:$R$20,0),2) -> 182 | J24: 70 | K24: 61.8 | L24: =100-K24 -> 38.2 | M24: =IF(L24<25,"Q1",IF(L24<50,"Q2",IF(L24<75,"Q3","Q4"))) -> Q2 | N24: =1213/483 -> 2.5113872 | O24: 0.00445
A25: ㅇ | B25: =B24+1 -> 17 | C25: Structures | D25: SCI(E) | E25: 2352-0124 | G25: 2352-0124 | H25: Engineering, Civil | I25: =INDEX($R$9:$T$20,MATCH($H25,$R$9:$R$20,0),2) -> 182 | J25: 35 | K25: 81 | L25: =100-K25 -> 19 | M25: =IF(L25<25,"Q1",IF(L25<50,"Q2",IF(L25<75,"Q3","Q4"))) -> Q1 | N25: =10190/2637 -> 3.8642397 | O25: 0.01888
A26: ㅇ | B26: =B25+1 -> 18 | C26: Structure and Infrastructure Engineering | D26: SCI(E) | E26: 1573-2479 | G26: 1744-8980 | H26: Engineering, Mechanical | I26: =INDEX($R$9:$T$20,MATCH($H26,$R$9:$R$20,0),2) -> 183 | J26: 64 | K26: 65.3 | L26: =100-K26 -> 34.7 | M26: =IF(L26<25,"Q1",IF(L26<50,"Q2",IF(L26<75,"Q3","Q4"))) -> Q2 | N26: =693/267 -> 2.5955056 | O26: 0.00428
A27: ㅇ | B27: =B26+1 -> 19 | C27: Computers and Geotechnics | D27: SCI(E) | E27: 0266-352X | G27: 1873-7633 | H27: Geosciences, Multidisciplinary | I27: =INDEX($R$9:$T$20,MATCH($H27,$R$9:$R$20,0),2) -> 254 | J27: 26 | K27: 90 | L27: =100-K27 -> 10 | M27: =IF(L27<25,"Q1",IF(L27<50,"Q2",IF(L27<75,"Q3","Q4"))) -> Q1 | N27: =5437/1032 -> 5.2684109 | O27: 0.01988
A28: ㅇ | B28: =B27+1 -> 20 | C28: Geomatics Natural Hazards & Risk | D28: SCI(E) | E28: 1947-5705 | G28: 1947-5713 | H28: Geosciences, Multidisciplinary | I28: =INDEX($R$9:$T$20,MATCH($H28,$R$9:$R$20,0),2) -> 254 | J28: 32 | K28: 87.6 | L28: =100-K28 -> 12.4 | M28: =IF(L28<25,"Q1",IF(L28<50,"Q2",IF(L28<75,"Q3","Q4"))) -> Q1 | N28: =1216/271 -> 4.4870849 | O28: 0.00384
A29: ㅇ | B29: =B28+1 -> 21 | C29: Engineering Geology | D29: SCI(E) | E29: 0013-7952 | G29: 1872-6917 | H29: Engineering, Geological | I29: =INDEX($R$9:$T$20,MATCH($H29,$R$9:$R$20,0),2) -> 63 | J29: 3 | K29: 96 | L29: =100-K29 -> 4 | M29: =IF(L29<25,"Q1",IF(L29<50,"Q2",IF(L29<75,"Q3","Q4"))) -> Q1 | N29: =5447/790 -> 6.8949367 | O29: 0.02439
A30: ㅇ | B30: =B29+1 -> 22 | C30: Canadian geotechnical journal | D30: SCI(E) | E30: 0008-3674 | G30: 1208-6010 | H30: Geosciences, Multidisciplinary | I30: =INDEX($R$9:$T$20,MATCH($H30,$R$9:$R$20,0),2) -> 254 | J30: 75 | K30: 70.7 | L30: =100-K30 -> 29.3 | M30: =IF(L30<25,"Q1",IF(L30<50,"Q2",IF(L30<75,"Q3","Q4"))) -> Q2 | N30: =1048/345 -> 3.0376812 | O30: 0.00659
A31: ㅇ | B31: =B30+1 -> 23 | C31: Geotechnique | D31: SCI(E) | E31: 0016-8505 | G31: 1751-7656 | H31: Engineering, Geological | I31: =INDEX($R$9:$T$20,MATCH($H31,$R$9:$R$20,0),2) -> 63 | J31: 12 | K31: 81.7 | L31: =100-K31 -> 18.3 | M31: =IF(L31<25,"Q1",IF(L31<50,"Q2",IF(L31<75,"Q3","Q4"))) -> Q1 | N31: =1190/283 -> 4.204947 | O31: 0.00613
A32: ㅇ | B32: =B31+1 -> 24 | C32: International Journal of Rock Mechanics and Mining Sciences | D32: SCI(E) | E32: 1365-1609 | G32: 1873-4545 | H32: Engineering, Geological | I32: =INDEX($R$9:$T$20,MATCH($H32,$R$9:$R$20,0),2) -> 63 | J32: 2 | K32: 97.6 | L32: =100-K32 -> 2.4 | M32: =IF(L32<25,"Q1",IF(L32<50,"Q2",IF(L32<75,"Q3","Q4"))) -> Q1 | N32: =3997/570 -> 7.0122807 | O32: 0.01715
A33: ㅇ | B33: =B32+1 -> 25 | C33: Cement and concrete research | D33: SCI(E) | E33: 0008-8846 | G33: 1873-3948 | H33: CONSTRUCTION & BUILDING TECHNOLOGY | I33: =INDEX($R$9:$T$20,MATCH($H33,$R$9:$R$20,0),2) -> 92 | J33: 1 | K33: 99.5 | L33: =100-K33 -> 0.5 | M33: =IF(L33<25,"Q1",IF(L33<50,"Q2",IF(L33<75,"Q3","Q4"))) -> Q1 | N33: =6526/601 -> 10.858569 | O33: 0.02798
A34: ㅇ | B34: =B33+1 -> 26 | C34: Advances in cement research | D34: SCI(E) | E34: 0951-7197 | G34: 1751-7605 | H34: CONSTRUCTION & BUILDING TECHNOLOGY | I34: =INDEX($R$9:$T$20,MATCH($H34,$R$9:$R$20,0),2) -> 92 | J34: 59 | K34: 36.4 | L34: =100-K34 -> 63.6 | M34: =IF(L34<25,"Q1",IF(L34<50,"Q2",IF(L34<75,"Q3","Q4"))) -> Q3 | N34: =171/118 -> 1.4491525 | O34: 0.00071
A35: ㅇ | B35: =B34+1 -> 27 | C35: Journal of engineering materials and technology | D35: SCI(E) | E35: 0094-4289 | G35: 1528-8889 | H35: Engineering, Mechanical | I35: =INDEX($R$9:$T$20,MATCH($H35,$R$9:$R$20,0),2) -> 183 | J35: 115 | K35: 37.4 | L35: =100-K35 -> 62.6 | M35: =IF(L35<25,"Q1",IF(L35<50,"Q2",IF(L35<75,"Q3","Q4"))) -> Q3 | N35: =125/85 -> 1.4705882 | O35: 0.00053
A36: ㅇ | B36: =B35+1 -> 28 | C36: Advances in Civil Engineering | D36: SCI(E) | E36: 1687-8086 | G36: 1687-8094 | H36: Construction & Building Technology | I36: =INDEX($R$9:$T$20,MATCH($H36,$R$9:$R$20,0),2) -> 92 | J36: 54 | K36: 41.8 | L36: =100-K36 -> 58.2 | M36: =IF(L36<25,"Q1",IF(L36<50,"Q2",IF(L36<75,"Q3","Q4"))) -> Q3 | N36: =2884/1926 -> 1.4974039 | O36: 0.01133
A37: ㅇ | B37: =B36+1 -> 29 | C37: Journal of Coastal Research | D37: SCI(E) | E37: 0749-0208 | G37: 1551-5036 | H37: GEOGRAPHY, PHYSICAL | I37: =INDEX($R$9:$T$20,MATCH($H37,$R$9:$R$20,0),2) -> 50 | J37: 47 | K37: 7 | L37: =100-K37 -> 93 | M37: =IF(L37<25,"Q1",IF(L37<50,"Q2",IF(L37<75,"Q3","Q4"))) -> Q4 | N37: =3016/2718 -> 1.1096394 | O37: 0.00807
A38: ㅇ | B38: =B37+1 -> 30 | C38: International Journal of Geo-Engineering | D38: SCI(E) | E38: 2092-9196 | G38: 2198-2783 | H38: Engineering, Geological | I38: =INDEX($R$9:$T$20,MATCH($H38,$R$9:$R$20,0),2) -> 63 | J38: 26 | K38: 59.5 | L38: =100-K38 -> 40.5 | M38: =IF(L38<25,"Q1",IF(L38<50,"Q2",IF(L38<75,"Q3","Q4"))) -> Q2 | N38: =127/48 -> 2.6458333 | O38: 0.00048
B39: =B38+1 -> 31
B40: =B39+1 -> 32
B41: =B40+1 -> 33
...

Sheet GSR group 저널논문 (2001~2024)
D2: 색상
E3: : 입력해야 할 부분 | K3: =COUNTIF(K6:K99,"=Q1")/COUNTIF(H6:H99,"=SCI(E)") -> 0.63513514
B5: 번호 | C5: 연도 | D5: 연번 | E5: 논문제목 | F5: 게재학술지명 | G5: 주저자 성명 | H5: 논문구분 | I5: IF | J5: ES | K5: Rating
B6: 1 | C6: 2001 | D6: 1 | E6: Non-linear one-dimensional seismic ground motion propagation in the Mississippi embayment | F6: Engineering Geology | H6: =INDEX(학술지정보!$C$9:$O$50,MATCH($F6,학술지정보!$C$9:$C$50,0),2) -> SCI(E) | I6: =IF(H6="SCOPUS","N.A.",INDEX(학술지정보!$C$9:$O$50,MATCH($F6,학술지정보!$C$9:$C$50,0),12)) -> 6.8949367 | J6: =IF(H6="SCOPUS","N.A.",INDEX(학술지정보!$C$9:$O$50,MATCH($F6,학술지정보!$C$9:$C$50,0),13)) -> 0.02439 | K6: =IF(H6="SCOPUS","N.A.",INDEX(학술지정보!$C$9:$O$50,MATCH($F6,학술지정보!$C$9:$C$50,0),11)) -> Q1
B7: =B6+1 -> 2 | C7: 2002 | D7: 1 | E7: Viscous damping formulation and high frequency motion propagation in non-linear site response analysis | F7: Soil Dynamics and Earthquake Engineering | H7: =INDEX(학술지정보!$C$9:$O$50,MATCH($F7,학술지정보!$C$9:$C$50,0),2) -> SCI(E) | I7: =IF(H7="SCOPUS","N.A.",INDEX(학술지정보!$C$9:$O$50,MATCH($F7,학술지정보!$C$9:$C$50,0),12)) -> 4.1788018 | J7: =IF(H7="SCOPUS","N.A.",INDEX(학술지정보!$C$9:$O$50,MATCH($F7,학술지정보!$C$9:$C$50,0),13)) -> 0.01773 | K7: =IF(H7="SCOPUS","N.A.",INDEX(학술지정보!$C$9:$O$50,MATCH($F7,학술지정보!$C$9:$C$50,0),11)) -> Q1
B8: =B7+1 -> 3 | C8: 2004 | D8: 1 | E8: Soil damping formulation in nonlinear time domain site response analysis | F8: Journal of earthquake engineering | H8: =INDEX(학술지정보!$C$9:$O$50,MATCH($F8,학술지정보!$C$9:$C$50,0),2) -> SCI(E) | I8: =IF(H8="SCOPUS","N.A.",INDEX(학술지정보!$C$9:$O$50,MATCH($F8,학술지정보!$C$9:$C$50,0),12)) -> 2.5113872 | J8: =IF(H8="SCOPUS","N.A.",INDEX(학술지정보!$C$9:$O$50,MATCH($F8,학술지정보!$C$9:$C$50,0),13)) -> 0.00445 | K8: =IF(H8="SCOPUS","N.A.",INDEX(학술지정보!$C$9:$O$50,MATCH($F8,학술지정보!$C$9:$C$50,0),11)) -> Q2
B9: =B8+1 -> 4 | C9: 2005 | D9: 1 | E9: Ovaling deformations of circular tunnels under seismic loading, an update on seismic design and analysis of underground structures | F9: Tunnelling and Underground Space Technology | H9: =INDEX(학술지정보!$C$9:$O$50,MATCH($F9,학술지정보!$C$9:$C$50,0),2) -> SCI(E) | I9: =IF(H9="SCOPUS","N.A.",INDEX(학술지정보!$C$9:$O$50,MATCH($F9,학술지정보!$C$9:$C$50,0),12)) -> 6.6583012 | J9: =IF(H9="SCOPUS","N.A.",INDEX(학술지정보!$C$9:$O$50,MATCH($F9,학술지정보!$C$9:$C$50,0),13)) -> 0.02221 | K9: =IF(H9="SCOPUS","N.A.",INDEX(학술지정보!$C$9:$O$50,MATCH($F9,학술지정보!$C$9:$C$50,0),11)) -> Q1
B10: =B9+1 -> 5 | C10: 2005 | D10: 2 | E10: Evaluation of seismic site factors in the Mississippi Embayment. II. Probabilistic seismic hazard analysis with nonlinear site effects | F10: Soil Dynamics and Earthquake Engineering | H10: =INDEX(학술지정보!$C$9:$O$50,MATCH($F10,학술지정보!$C$9:$C$50,0),2) -> SCI(E) | I10: =IF(H10="SCOPUS","N.A.",INDEX(학술지정보!$C$9:$O$50,MATCH($F10,학술지정보!$C$9:$C$50,0),12)) -> 4.1788018 | J10: =IF(H10="SCOPUS","N.A.",INDEX(학술지정보!$C$9:$O$50,MATCH($F10,학술지정보!$C$9:$C$50,0),13)) -> 0.01773 | K10: =IF(H10="SCOPUS","N.A.",INDEX(학술지정보!$C$9:$O$50,MATCH($F10,학술지정보!$C$9:$C$50,0),11)) -> Q1
B11: =B10+1 -> 6 | C11: 2005 | D11: =D10+1 -> 3 | E11: Evaluation of seismic site factors in the Mississippi Embayment. I. Estimation of dynamic properties | F11: Soil Dynamics and Earthquake Engineering | G11: 박두희 | H11: =INDEX(학술지정보!$C$9:$O$50,MATCH($F11,학술지정보!$C$9:$C$50,0),2) -> SCI(E) | I11: =IF(H11="SCOPUS","N.A.",INDEX(학술지정보!$C$9:$O$50,MATCH($F11,학술지정보!$C$9:$C$50,0),12)) -> 4.1788018 | J11: =IF(H11="SCOPUS","N.A.",INDEX(학술지정보!$C$9:$O$50,MATCH($F11,학술지정보!$C$9:$C$50,0),13)) -> 0.01773 | K11: =IF(H11="SCOPUS","N.A.",INDEX(학술지정보!$C$9:$O$50,MATCH($F11,학술지정보!$C$9:$C$50,0),11)) -> Q1
B12: =B11+1 -> 7 | C12: 2006 | D12: 1 | E12: Construction of double track subway tunnel in the alluvial soils with shallow overburden | F12: Tunnelling and Underground Space Technology | H12: =INDEX(학술지정보!$C$9:$O$50,MATCH($F12,학술지정보!$C$9:$C$50,0),2) -> SCI(E) | I12: =IF(H12="SCOPUS","N.A.",INDEX(학술지정보!$C$9:$O$50,MATCH($F12,학술지정보!$C$9:$C$50,0),12)) -> 6.6583012 | J12: =IF(H12="SCOPUS","N.A.",INDEX(학술지정보!$C$9:$O$50,MATCH($F12,학술지정보!$C$9:$C$50,0),13)) -> 0.02221 | K12: =IF(H12="SCOPUS","N.A.",INDEX(학술지정보!$C$9:$O$50,MATCH($F12,학술지정보!$C$9:$C$50,0),11)) -> Q1
B13: =B12+1 -> 8 | C13: 2007 | D13: 1 | E13: Simulation of Inundation at Imwon Port during 1983 Central East Sea Tsunami | F13: Journal of Coastal Research | G13: 박두희 | H13: =INDEX(학술지정보!$C$9:$O$50,MATCH($F13,학술지정보!$C$9:$C$50,0),2) -> SCI(E) | I13: =IF(H13="SCOPUS","N.A.",INDEX(학술지정보!$C$9:$O$50,MATCH($F13,학술지정보!$C$9:$C$50,0),12)) -> 1.1096394 | J13: =IF(H13="SCOPUS","N.A.",INDEX(학술지정보!$C$9:$O$50,MATCH($F13,학술지정보!$C$9:$C$50,0),13)) -> 0.00807 | K13: =IF(H13="SCOPUS","N.A.",INDEX(학술지정보!$C$9:$O$50,MATCH($F13,학술지정보!$C$9:$C$50,0),11)) -> Q4
B14: =B13+1 -> 9 | C14: 2008 | D14: 1 | E14: Effect of limestone filler on the deterioration of mortars and pastes exposed to sulfate solutions at ambient temperature | F14: Cement and concrete research | H14: =INDEX(학술지정보!$C$9:$O$50,MATCH($F14,학술지정보!$C$9:$C$50,0),2) -> SCI(E) | I14: =IF(H14="SCOPUS","N.A.",INDEX(학술지정보!$C$9:$O$50,MATCH($F14,학술지정보!$C$9:$C$50,0),12)) -> 10.858569 | J14: =IF(H14="SCOPUS","N.A.",INDEX(학술지정보!$C$9:$O$50,MATCH($F14,학술지정보!$C$9:$C$50,0),13)) -> 0.02798 | K14: =IF(H14="SCOPUS","N.A.",INDEX(학술지정보!$C$9:$O$50,MATCH($F14,학술지정보!$C$9:$C$50,0),11)) -> Q1
B15: =B14+1 -> 10 | C15: 2008 | D15: 2 | E15: Rate-dependent soil behavior in seismic site response analysis | F15: Canadian Geotechnical Journal | G15: 박두희 | H15: =INDEX(학술지정보!$C$9:$O$50,MATCH($F15,학술지정보!$C$9:$C$50,0),2) -> SCI(E) | I15: =IF(H15="SCOPUS","N.A.",INDEX(학술지정보!$C$9:$O$50,MATCH($F15,학술지정보!$C$9:$C$50,0),12)) -> 3.0376812 | J15: =IF(H15="SCOPUS","N.A.",INDEX(학술지정보!$C$9:$O$50,MATCH($F15,학술지정보!$C$9:$C$50,0),13)) -> 0.00659 | K15: =IF(H15="SCOPUS","N.A.",INDEX(학술지정보!$C$9:$O$50,MATCH($F15,학술지정보!$C$9:$C$50,0),11)) -> Q2
B16: =B15+1 -> 11 | C16: 2008 | D16: 3 | E16: Soil-column depth-dependent seismic site coefficients and hazard maps for the upper Mississippi Embayment | F16: Bulletin of the Seismological Society of America | H16: =INDEX(학술지정보!$C$9:$O$50,MATCH($F16,학술지정보!$C$9:$C$50,0),2) -> SCI(E) | I16: =IF(H16="SCOPUS","N.A.",INDEX(학술지정보!$C$9:$O$50,MATCH($F16,학술지정보!$C$9:$C$50,0),12)) -> 2.6493506 | J16: =IF(H16="SCOPUS","N.A.",INDEX(학술지정보!$C$9:$O$50,MATCH($F16,학술지정보!$C$9:$C$50,0),13)) -> 0.00845 | K16: =IF(H16="SCOPUS","N.A.",INDEX(학술지정보!$C$9:$O$50,MATCH($F16,학술지정보!$C$9:$C$50,0),11)) -> Q2
B17: =B16+1 -> 12 | C17: 2009 | D17: 1 | E17: Simulation of tunnel response under spatially varying ground motion | F17: Soil Dynamics and Earthquake Engineering | G17: 박두희 | H17: =INDEX(학술지정보!$C$9:$O$50,MATCH($F17,학술지정보!$C$9:$C$50,0),2) -> SCI(E) | I17: =IF(H17="SCOPUS","N.A.",INDEX(학술지정보!$C$9:$O$50,MATCH($F17,학술지정보!$C$9:$C$50,0),12)) -> 4.1788018 | J17: =IF(H17="SCOPUS","N.A.",INDEX(학술지정보!$C$9:$O$50,MATCH($F17,학술지정보!$C$9:$C$50,0),13)) -> 0.01773 | K17: =IF(H17="SCOPUS","N.A.",INDEX(학술지정보!$C$9:$O$50,MATCH($F17,학술지정보!$C$9:$C$50,0),11)) -> Q1
B18: =B17+1 -> 13 | C18: 2009 | D18: 2 | E18: Evaluation of liquefaction potential of port structures with earthquake magnitude adjustment | F18: Journal of Coastal Research | G18: 박두희 | H18: =INDEX(학술지정보!$C$9:$O$50,MATCH($F18,학술지정보!$C$9:$C$50,0),2) -> SCI(E) | I18: =IF(H18="SCOPUS","N.A.",INDEX(학술지정보!$C$9:$O$50,MATCH($F18,학술지정보!$C$9:$C$50,0),12)) -> 1.1096394 | J18: =IF(H18="SCOPUS","N.A.",INDEX(학술지정보!$C$9:$O$50,MATCH($F18,학술지정보!$C$9:$C$50,0),13)) -> 0.00807 | K18: =IF(H18="SCOPUS","N.A.",INDEX(학술지정보!$C$9:$O$50,MATCH($F18,학술지정보!$C$9:$C$50,0),11)) -> Q4
B19: =B18+1 -> 14 | C19: 2010 | D19: 1 | E19: Development of generalised formula for dynamic active earth pressure | F19: Geotechnique | G19: 박두희 | H19: =INDEX(학술지정보!$C$9:$O$50,MATCH($F19,학술지정보!$C$9:$C$50,0),2) -> SCI(E) | I19: =IF(H19="SCOPUS","N.A.",INDEX(학술지정보!$C$9:$O$50,MATCH($F19,학술지정보!$C$9:$C$50,0),12)) -> 4.204947 | J19: =IF(H19="SCOPUS","N.A.",INDEX(학술지정보!$C$9:$O$50,MATCH($F19,학술지정보!$C$9:$C$50,0),13)) -> 0.00613 | K19: =IF(H19="SCOPUS","N.A.",INDEX(학술지정보!$C$9:$O$50,MATCH($F19,학술지정보!$C$9:$C$50,0),11)) -> Q1
B20: =B19+1 -> 15 | C20: 2010 | D20: 2 | E20: Flexural rigidity and ductility of high-strength reinforced polyester polymer concrete beams | F20: Advances in cement research | G20: 박두희 | H20: =INDEX(학술지정보!$C$9:$O$50,MATCH($F20,학술지정보!$C$9:$C$50,0),2) -> SCI(E) | I20: =IF(H20="SCOPUS","N.A.",INDEX(학술지정보!$C$9:$O$50,MATCH($F20,학술지정보!$C$9:$C$50,0),12)) -> 1.4491525 | J20: =IF(H20="SCOPUS","N.A.",INDEX(학술지정보!$C$9:$O$50,MATCH($F20,학술지정보!$C$9:$C$50,0),13)) -> 0.00071 | K20: =IF(H20="SCOPUS","N.A.",INDEX(학술지정보!$C$9:$O$50,MATCH($F20,학술지정보!$C$9:$C$50,0),11)) -> Q3
B21: =B20+1 -> 16 | C21: 2011 | D21: 1 | E21: Experimental and numerical analysis of an opening in a jointed rock mass under biaxial compression | F21: International Journal of Rock Mechanics and Mining Sciences | H21: =INDEX(학술지정보!$C$9:$O$50,MATCH($F21,학술지정보!$C$9:$C$50,0),2) -> SCI(E) | I21: =IF(H21="SCOPUS","N.A.",INDEX(학술지정보!$C$9:$O$50,MATCH($F21,학술지정보!$C$9:$C$50,0),12)) -> 7.0122807 | J21: =IF(H21="SCOPUS","N.A.",INDEX(학술지정보!$C$9:$O$50,MATCH($F21,학술지정보!$C$9:$C$50,0),13)) -> 0.01715 | K21: =IF(H21="SCOPUS","N.A.",INDEX(학술지정보!$C$9:$O$50,MATCH($F21,학술지정보!$C$9:$C$50,0),11)) -> Q1
B22: =B21+1 -> 17 | C22: 2012 | D22: 1 | E22: Analysis of round robin test on seismic site response analysis | F22: KSCE Journal of Civil Engineering | G22: 박두희 | H22: =INDEX(학술지정보!$C$9:$O$50,MATCH($F22,학술지정보!$C$9:$C$50,0),2) -> SCI(E) | I22: =IF(H22="SCOPUS","N.A.",INDEX(학술지정보!$C$9:$O$50,MATCH($F22,학술지정보!$C$9:$C$50,0),12)) -> 1.9105012 | J22: =IF(H22="SCOPUS","N.A.",INDEX(학술지정보!$C$9:$O$50,MATCH($F22,학술지정보!$C$9:$C$50,0),13)) -> 0.00712 | K22: =IF(H22="SCOPUS","N.A.",INDEX(학술지정보!$C$9:$O$50,MATCH($F22,학술지정보!$C$9:$C$50,0),11)) -> Q2
B23: =B22+1 -> 18 | C23: 2012 | D23: 2 | E23: Development of probabilistic seismic site coefficients of Korea | F23: Soil Dynamics and Earthquake Engineering | G23: 박두희 | H23: =INDEX(학술지정보!$C$9:$O$50,MATCH($F23,학술지정보!$C$9:$C$50,0),2) -> SCI(E) | I23: =IF(H23="SCOPUS","N.A.",INDEX(학술지정보!$C$9:$O$50,MATCH($F23,학술지정보!$C$9:$C$50,0),12)) -> 4.1788018 | J23: =IF(H23="SCOPUS","N.A.",INDEX(학술지정보!$C$9:$O$50,MATCH($F23,학술지정보!$C$9:$C$50,0),13)) -> 0.01773 | K23: =IF(H23="SCOPUS","N.A.",INDEX(학술지정보!$C$9:$O$50,MATCH($F23,학술지정보!$C$9:$C$50,0),11)) -> Q1
B24: =B23+1 -> 19 | C24: 2013 | D24: 1 | E24: Development of a loading platen containing a cylindrical roller bearing to reduce frictional constraint at the boundary | F24: International Journal of Rock Mechanics and Mining Sciences | H24: =INDEX(학술지정보!$C$9:$O$50,MATCH($F24,학술지정보!$C$9:$C$50,0),2) -> SCI(E) | I24: =IF(H24="SCOPUS","N.A.",INDEX(학술지정보!$C$9:$O$50,MATCH($F24,학술지정보!$C$9:$C$50,0),12)) -> 7.0122807 | J24: =IF(H24="SCOPUS","N.A.",INDEX(학술지정보!$C$9:$O$50,MATCH($F24,학술지정보!$C$9:$C$50,0),13)) -> 0.01715 | K24: =IF(H24="SCOPUS","N.A.",INDEX(학술지정보!$C$9:$O$50,MATCH($F24,학술지정보!$C$9:$C$50,0),11)) -> Q1
B25: =B24+1 -> 20 | C25: 2013 | D25: 2 | E25: Computational coupled method for multiscale and phase analysis | F25: Journal of engineering materials and technology | H25: =INDEX(학술지정보!$C$9:$O$50,MATCH($F25,학술지정보!$C$9:$C$50,0),2) -> SCI(E) | I25: =IF(H25="SCOPUS","N.A.",INDEX(학술지정보!$C$9:$O$50,MATCH($F25,학술지정보!$C$9:$C$50,0),12)) -> 1.4705882 | J25: =IF(H25="SCOPUS","N.A.",INDEX(학술지정보!$C$9:$O$50,MATCH($F25,학술지정보!$C$9:$C$50,0),13)) -> 0.00053 | K25: =IF(H25="SCOPUS","N.A.",INDEX(학술지정보!$C$9:$O$50,MATCH($F25,학술지정보!$C$9:$C$50,0),11)) -> Q3
B26: =B25+1 -> 21 | C26: 2014 | D26: 1 | E26: Selection of the optimal frequencies of viscous damping formulation in nonlinear time-domain site response analysis | F26: Soil Dynamics and Earthquake Engineering | G26: 박두희 | H26: =INDEX(학술지정보!$C$9:$O$50,MATCH($F26,학술지정보!$C$9:$C$50,0),2) -> SCI(E) | I26: =IF(H26="SCOPUS","N.A.",INDEX(학술지정보!$C$9:$O$50,MATCH($F26,학술지정보!$C$9:$C$50,0),12)) -> 4.1788018 | J26: =IF(H26="SCOPUS","N.A.",INDEX(학술지정보!$C$9:$O$50,MATCH($F26,학술지정보!$C$9:$C$50,0),13)) -> 0.01773 | K26: =IF(H26="SCOPUS","N.A.",INDEX(학술지정보!$C$9:$O$50,MATCH($F26,학술지정보!$C$9:$C$50,0),11)) -> Q1
B27: =B26+1 -> 22 | C27: 2015 | D27: 1 | E27: Pore pressure model based on accumulated stress | F27: Bulletin of Earthquake Engineering | G27: 박두희 | H27: =INDEX(학술지정보!$C$9:$O$50,MATCH($F27,학술지정보!$C$9:$C$50,0),2) -> SCI(E) | I27: =IF(H27="SCOPUS","N.A.",INDEX(학술지정보!$C$9:$O$50,MATCH($F27,학술지정보!$C$9:$C$50,0),12)) -> 3.7847866 | J27: =IF(H27="SCOPUS","N.A.",INDEX(학술지정보!$C$9:$O$50,MATCH($F27,학술지정보!$C$9:$C$50,0),13)) -> 0.00883 | K27: =IF(H27="SCOPUS","N.A.",INDEX(학술지정보!$C$9:$O$50,MATCH($F27,학술지정보!$C$9:$C$50,0),11)) -> Q1
B28: =B27+1 -> 23 | C28: 2015 | D28: 2 | E28: Prediction of seismic displacement of dry mountain slopes composed of a soft thin uniform layer | F28: Soil Dynamics and Earthquake Engineering | G28: 박두희 | H28: =INDEX(학술지정보!$C$9:$O$50,MATCH($F28,학술지정보!$C$9:$C$50,0),2) -> SCI(E) | I28: =IF(H28="SCOPUS","N.A.",INDEX(학술지정보!$C$9:$O$50,MATCH($F28,학술지정보!$C$9:$C$50,0),12)) -> 4.1788018 | J28: =IF(H28="SCOPUS","N.A.",INDEX(학술지정보!$C$9:$O$50,MATCH($F28,학술지정보!$C$9:$C$50,0),13)) -> 0.01773 | K28: =IF(H28="SCOPUS","N.A.",INDEX(학술지정보!$C$9:$O$50,MATCH($F28,학술지정보!$C$9:$C$50,0),11)) -> Q1
B29: =B28+1 -> 24 | C29: 2016 | D29: 1 | E29: Damage analysis of cut-and-cover tunnel structures under seismic loading | F29: Bulletin of Earthquake Engineering | G29: 박두희 | H29: =INDEX(학술지정보!$C$9:$O$50,MATCH($F29,학술지정보!$C$9:$C$50,0),2) -> SCI(E) | I29: =IF(H29="SCOPUS","N.A.",INDEX(학술지정보!$C$9:$O$50,MATCH($F29,학술지정보!$C$9:$C$50,0),12)) -> 3.7847866 | J29: =IF(H29="SCOPUS","N.A.",INDEX(학술지정보!$C$9:$O$50,MATCH($F29,학술지정보!$C$9:$C$50,0),13)) -> 0.00883 | K29: =IF(H29="SCOPUS","N.A.",INDEX(학술지정보!$C$9:$O$50,MATCH($F29,학술지정보!$C$9:$C$50,0),11)) -> Q1
B30: =B29+1 -> 25 | C30: 2016 | D30: 2 | E30: Effect of freezing saturated sandy soil under undrained condition on a buried steel pipe | F30: International Journal of Control and Automation | G30: 박두희 | H30: =INDEX(학술지정보!$C$9:$O$50,MATCH($F30,학술지정보!$C$9:$C$50,0),2) -> SCOPUS | I30: =IF(H30="SCOPUS","N.A.",INDEX(학술지정보!$C$9:$O$50,MATCH($F30,학술지정보!$C$9:$C$50,0),12)) -> N.A. | J30: =IF(H30="SCOPUS","N.A.",INDEX(학술지정보!$C$9:$O$50,MATCH($F30,학술지정보!$C$9:$C$50,0),13)) -> N.A. | K30: =IF(H30="SCOPUS","N.A.",INDEX(학술지정보!$C$9:$O$50,MATCH($F30,학술지정보!$C$9:$C$50,0),11)) -> N.A.
B31: =B30+1 -> 26 | C31: 2016 | D31: 3 | E31: Vertical bearing capacity of bucket foundations in sand | F31: Ocean Engineering | G31: 박두희 | H31: =INDEX(학술지정보!$C$9:$O$50,MATCH($F31,학술지정보!$C$9:$C$50,0),2) -> SCI(E) | I31: =IF(H31="SCOPUS","N.A.",INDEX(학술지정보!$C$9:$O$50,MATCH($F31,학술지정보!$C$9:$C$50,0),12)) -> 4.5597586 | J31: =IF(H31="SCOPUS","N.A.",INDEX(학술지정보!$C$9:$O$50,MATCH($F31,학술지정보!$C$9:$C$50,0),13)) -> 0.04254 | K31: =IF(H31="SCOPUS","N.A.",INDEX(학술지정보!$C$9:$O$50,MATCH($F31,학술지정보!$C$9:$C$50,0),11)) -> Q1
B32: =B31+1 -> 27 | C32: 2017 | D32: 1 | E32: Development of normalized liquefaction resistance curve for clean sands | F32: Bulletin of earthquake engineering | G32: 박두희 | H32: =INDEX(학술지정보!$C$9:$O$50,MATCH($F32,학술지정보!$C$9:$C$50,0),2) -> SCI(E) | I32: =IF(H32="SCOPUS","N.A.",INDEX(학술지정보!$C$9:$O$50,MATCH($F32,학술지정보!$C$9:$C$50,0),12)) -> 3.7847866 | J32: =IF(H32="SCOPUS","N.A.",INDEX(학술지정보!$C$9:$O$50,MATCH($F32,학술지정보!$C$9:$C$50,0),13)) -> 0.00883 | K32: =IF(H32="SCOPUS","N.A.",INDEX(학술지정보!$C$9:$O$50,MATCH($F32,학술지정보!$C$9:$C$50,0),11)) -> Q1
B33: =B32+1 -> 28 | C33: 2017 | D33: 2 | E33: Vertical bearing capacity of bucket foundation in sand overlying clay | F33: Ocean Engineering | G33: 박두희 | H33: =INDEX(학술지정보!$C$9:$O$50,MATCH($F33,학술지정보!$C$9:$C$50,0),2) -> SCI(E) | I33: =IF(H33="SCOPUS","N.A.",INDEX(학술지정보!$C$9:$O$50,MATCH($F33,학술지정보!$C$9:$C$50,0),12)) -> 4.5597586 | J33: =IF(H33="SCOPUS","N.A.",INDEX(학술지정보!$C$9:$O$50,MATCH($F33,학술지정보!$C$9:$C$50,0),13)) -> 0.04254 | K33: =IF(H33="SCOPUS","N.A.",INDEX(학술지정보!$C$9:$O$50,MATCH($F33,학술지정보!$C$9:$C$50,0),11)) -> Q1
B34: =B33+1 -> 29 | C34: 2017 | D34: 3 | E34: Detection of cavities around concrete sewage pipelines using impact-echo method | F34: Tunnelling and Underground Space Technology | G34: 박두희 | H34: =INDEX(학술지정보!$C$9:$O$50,MATCH($F34,학술지정보!$C$9:$C$50,0),2) -> SCI(E) | I34: =IF(H34="SCOPUS","N.A.",INDEX(학술지정보!$C$9:$O$50,MATCH($F34,학술지정보!$C$9:$C$50,0),12)) -> 6.6583012 | J34: =IF(H34="SCOPUS","N.A.",INDEX(학술지정보!$C$9:$O$50,MATCH($F34,학술지정보!$C$9:$C$50,0),13)) -> 0.02221 | K34: =IF(H34="SCOPUS","N.A.",INDEX(학술지정보!$C$9:$O$50,MATCH($F34,학술지정보!$C$9:$C$50,0),11)) -> Q1
B35: =B34+1 -> 30 | C35: 2017 | D35: 4 | E35: Supplementing Vs30 with H/V Spectral Ratios for Predicting Site Effects | F35: Bulletin of the Seismological Society of America | G35: 박두희 | H35: =INDEX(학술지정보!$C$9:$O$50,MATCH($F35,학술지정보!$C$9:$C$50,0),2) -> SCI(E) | I35: =IF(H35="SCOPUS","N.A.",INDEX(학술지정보!$C$9:$O$50,MATCH($F35,학술지정보!$C$9:$C$50,0),12)) -> 2.6493506 | J35: =IF(H35="SCOPUS","N.A.",INDEX(학술지정보!$C$9:$O$50,MATCH($F35,학술지정보!$C$9:$C$50,0),13)) -> 0.00845 | K35: =IF(H35="SCOPUS","N.A.",INDEX(학술지정보!$C$9:$O$50,MATCH($F35,학술지정보!$C$9:$C$50,0),11)) -> Q2
B36: =B35+1 -> 31 | C36: 2017 | D36: 5 | E36: Prediction of near-field wave attenuation due to a spherical blast source | F36: Rock Mechanics and Rock Engineering | G36: 박두희 | H36: =INDEX(학술지정보!$C$9:$O$50,MATCH($F36,학술지정보!$C$9:$C$50,0),2) -> SCI(E) | I36: =IF(H36="SCOPUS","N.A.",INDEX(학술지정보!$C$9:$O$50,MATCH($F36,학술지정보!$C$9:$C$50,0),12)) -> 5.4670588 | J36: =IF(H36="SCOPUS","N.A.",INDEX(학술지정보!$C$9:$O$50,MATCH($F36,학술지정보!$C$9:$C$50,0),13)) -> 0.01961 | K36: =IF(H36="SCOPUS","N.A.",INDEX(학술지정보!$C$9:$O$50,MATCH($F36,학술지정보!$C$9:$C$50,0),11)) -> Q1
B37: =B36+1 -> 32 | C37: 2017 | D37: 6 | E37: USGS hazard map compatible depth-dependent seismic site coefficients for the Upper Mississippi Embayment | F37: KSCE Journal of Civil Engineering | G37: 박두희 | H37: =INDEX(학술지정보!$C$9:$O$50,MATCH($F37,학술지정보!$C$9:$C$50,0),2) -> SCI(E) | I37: =IF(H37="SCOPUS","N.A.",INDEX(학술지정보!$C$9:$O$50,MATCH($F37,학술지정보!$C$9:$C$50,0),12)) -> 1.9105012 | J37: =IF(H37="SCOPUS","N.A.",INDEX(학술지정보!$C$9:$O$50,MATCH($F37,학술지정보!$C$9:$C$50,0),13)) -> 0.00712 | K37: =IF(H37="SCOPUS","N.A.",INDEX(학술지정보!$C$9:$O$50,MATCH($F37,학술지정보!$C$9:$C$50,0),11)) -> Q2
... B40: =B39+1 -> 35 | C40: 2019 | D40: 1 | E40: Effect of Flexibility Ratio on Seismic Response of Cut‐and‐Cover Box Tunnel | F40: Advances in Civil Engineering | G40: 박두희 | H40: =INDEX(학술지정보!$C$9:$O$50,MATCH($F40,학술지정보!$C$9:$C$50,0),2) -> SCI(E) | I40: =IF(H40="SCOPUS","N.A.",INDEX(학술지정보!$C$9:$O$50,MATCH($F40,학술지정보!$C$9:$C$50,0),12)) -> 1.4974039 | J40: =IF(H40="SCOPUS","N.A.",INDEX(학술지정보!$C$9:$O$50,MATCH($F40,학술지정보!$C$9:$C$50,0),13)) -> 0.01133 | K40: =IF(H40="SCOPUS","N.A.",INDEX(학술지정보!$C$9:$O$50,MATCH($F40,학술지정보!$C$9:$C$50,0),11)) -> Q3
B41: =B40+1 -> 36 | C41: 2019 | D41: 2 | E41: Seismic vulnerability assessment of rectangular cut-and-cover subway tunnels | F41: Tunnelling and Underground Space Technology | H41: =INDEX(학술지정보!$C$9:$O$50,MATCH($F41,학술지정보!$C$9:$C$50,0),2) -> SCI(E) | I41: =IF(H41="SCOPUS","N.A.",INDEX(학술지정보!$C$9:$O$50,MATCH($F41,학술지정보!$C$9:$C$50,0),12)) -> 6.6583012 | J41: =IF(H41="SCOPUS","N.A.",INDEX(학술지정보!$C$9:$O$50,MATCH($F41,학술지정보!$C$9:$C$50,0),13)) -> 0.02221 | K41: =IF(H41="SCOPUS","N.A.",INDEX(학술지정보!$C$9:$O$50,MATCH($F41,학술지정보!$C$9:$C$50,0),11)) -> Q1
B42: =B41+1 -> 37 | C42: 2019 | D42: 3 | E42: Seismic damage analysis of box metro tunnels accounting for aspect ratio and shear failure | F42: Applied Sciences-Basel | G42: 박두희 | H42: =INDEX(학술지정보!$C$9:$O$50,MATCH($F42,학술지정보!$C$9:$C$50,0),2) -> SCI(E) | I42: =IF(H42="SCOPUS","N.A.",INDEX(학술지정보!$C$9:$O$50,MATCH($F42,학술지정보!$C$9:$C$50,0),12)) -> 2.4518839 | J42: =IF(H42="SCOPUS","N.A.",INDEX(학술지정보!$C$9:$O$50,MATCH($F42,학술지정보!$C$9:$C$50,0),13)) -> 0.11103 | K42: =IF(H42="SCOPUS","N.A.",INDEX(학술지정보!$C$9:$O$50,MATCH($F42,학술지정보!$C$9:$C$50,0),11)) -> Q1
B43: =B42+1 -> 38 | C43: 2019 | D43: 4 | E43: Multi-platform soil-structure interaction simulation of Daikai subway tunnel during the 1995 Kobe earthquake | F43: Soil Dynamics and Earthquake Engineering | H43: =INDEX(학술지정보!$C$9:$O$50,MATCH($F43,학술지정보!$C$9:$C$50,0),2) -> SCI(E) | I43: =IF(H43="SCOPUS","N.A.",INDEX(학술지정보!$C$9:$O$50,MATCH($F43,학술지정보!$C$9:$C$50,0),12)) -> 4.1788018 | J43: =IF(H43="SCOPUS","N.A.",INDEX(학술지정보!$C$9:$O$50,MATCH($F43,학술지정보!$C$9:$C$50,0),13)) -> 0.01773 | K43: =IF(H43="SCOPUS","N.A.",INDEX(학술지정보!$C$9:$O$50,MATCH($F43,학술지정보!$C$9:$C$50,0),11)) -> Q1
B44: =B43+1 -> 39 | C44: 2019 | D44: 5 | E44: Estimation of seismically-induced crest settlement of earth core rockfill dams | F44: Applied Sciences-Basel | G44: 박두희 | H44: =INDEX(학술지정보!$C$9:$O$50,MATCH($F44,학술지정보!$C$9:$C$50,0),2) -> SCI(E) | I44: =IF(H44="SCOPUS","N.A.",INDEX(학술지정보!$C$9:$O$50,MATCH($F44,학술지정보!$C$9:$C$50,0),12)) -> 2.4518839 | J44: =IF(H44="SCOPUS","N.A.",INDEX(학술지정보!$C$9:$O$50,MATCH($F44,학술지정보!$C$9:$C$50,0),13)) -> 0.11103 | K44: =IF(H44="SCOPUS","N.A.",INDEX(학술지정보!$C$9:$O$50,MATCH($F44,학술지정보!$C$9:$C$50,0),11)) -> Q1
...

Sheet GSR group 국내논문 (2006~2024)
D2: 색상
E3: : 입력해야 할 부분
B8: 번호 | C8: 연도 | D8: 연번 | E8: 논문제목(한글) | F8: 논문제목(영어) | G8: 게재정보 | S8: 총 저자
G9: 게재논문집명(한글) | H9: 게재논문집명(영어) | I9: 학술지구분 | J9: ISSN | K9: e-ISSN | L9: DOI | M9: 학술대회발표구분 | N9: Volume (권) | O9: Issue (호) | P9: No. | Q9: 쪽 | R9: 연월(YYYYMM) | S9: 제1저자 | T9: 교신 저자 | U9: 기타 저자1 | V9: 기타 저자2 | W9: 기타 저자3 | X9: 기타 저자4 | Y9: 기타 저자5 | Z9: 기타 저자6 | AA9: 기타 저자7 | AB9: 총 저자수 (T)
B10: 1 | C10: 2005 | D10: 1 | E10: "국내 내륙의 설계 지반 운동 결정을 위한 지반 증폭 계수 및 지반 분류 체계 제안" 논문에 관한 토의 | F10: Development of equivalent linear algorithm procedure that accounts for the loading frequency dependent soil behavior | G10: 한국지반공학회 논문집 | H10: Journal of the Korean Geotechnical Society | I10: =INDEX(학술지정보!$C$9:$O$50,MATCH($H10,학술지정보!$C$9:$C$50,0),2) -> 비SCI | J10: {=INDEX(학술지정보!$C$9:$O$50,MATCH($H10,학술지정보!$C$9:$C$50,0),3)} -> 1229-2427 | K10: {=IF(INDEX(학술지정보!$C$9:$O$50,MATCH($H10,학술지정보!$C$9:$C$50,0),5)=0,"",INDEX(학술지정보!$C$9:$O$50,MATCH($H10,학술지정보!$C$9:$C$50,0),5))} -> 2288-646X | AB10: =COUNTA(S10:AA10) -> 0
B11: =B10+1 -> 2 | C11: 2006 | D11: 1 | E11: 공간적 변이성을 고려한 지진파 생성 | F11: Spatially variable ground motion simulation | G11: 한국지반공학회 논문집 | H11: Journal of the Korean Geotechnical Society | I11: =INDEX(학술지정보!$C$9:$O$50,MATCH($H11,학술지정보!$C$9:$C$50,0),2) -> 비SCI | J11: {=INDEX(학술지정보!$C$9:$O$50,MATCH($H11,학술지정보!$C$9:$C$50,0),3)} -> 1229-2427 | K11: {=IF(INDEX(학술지정보!$C$9:$O$50,MATCH($H11,학술지정보!$C$9:$C$50,0),5)=0,"",INDEX(학술지정보!$C$9:$O$50,MATCH($H11,학술지정보!$C$9:$C$50,0),5))} -> 2288-646X
B12: =B11+1 -> 3 | C12: 2006 | D12: 2 | E12: 하중의 주파수에 지배받는 흙의 동적거동을 고려하는 등가선형해석방법 개발 | F12: Development of equivalent linear algorithm procedure that accounts for the loading frequency dependent soil behavior | G12: 한국지반공학회 논문집 | H12: Journal of the Korean Geotechnical Society | I12: =INDEX(학술지정보!$C$9:$O$50,MATCH($H12,학술지정보!$C$9:$C$50,0),2) -> 비SCI | J12: {=INDEX(학술지정보!$C$9:$O$50,MATCH($H12,학술지정보!$C$9:$C$50,0),3)} -> 1229-2427 | K12: {=IF(INDEX(학술지정보!$C$9:$O$50,MATCH($H12,학술지정보!$C$9:$C$50,0),5)=0,"",INDEX(학술지정보!$C$9:$O$50,MATCH($H12,학술지정보!$C$9:$C$50,0),5))} -> 2288-646X | AB12: =COUNTA(S12:AA12) -> 0
B13: =B12+1 -> 4 | C13: 2006 | D13: 3 | E13: 하중의 주파수에 의하여 지배받은 흙의 동적 거동이 부지증폭현상에 미치는 영향 | F13: Effect of Loading Frequency Dependent Soil Behavior on Seismic Site Effects | G13: 한국지반공학회 논문집 | H13: Journal of the Korean Geotechnical Society
B14: =B13+1 -> 5 | C14: 2007 | D14: 1 | E14: Round Robin Test 기법을 통한 다양한 지반응답해석 접근법 비교 연구 | F14: A Comparative Study of Various Approaches of Seismic Ground Response Analyses by Using a Round Robin Test Methodology | G14: 한국지반공학회 논문집 | H14: Journal of the Korean Geotechnical Society | I14: =INDEX(학술지정보!$C$9:$O$50,MATCH($H14,학술지정보!$C$9:$C$50,0),2) -> 비SCI | J14: {=INDEX(학술지정보!$C$9:$O$50,MATCH($H14,학술지정보!$C$9:$C$50,0),3)} -> 1229-2427 | K14: {=IF(INDEX(학술지정보!$C$9:$O$50,MATCH($H14,학술지정보!$C$9:$C$50,0),5)=0,"",INDEX(학술지정보!$C$9:$O$50,MATCH($H14,학술지정보!$C$9:$C$50,0),5))} -> 2288-646X | AB14: =COUNTA(S14:AA14) -> 0
B15: =B14+1 -> 6 | C15: 2007 | D15: 2 | E15: 지반응답해석 Round Robin Test 결과 종합적 분석 연구 | F15: Comprehensive Evaluation of Results of Ground Response analysis Round Robin Test | G15: 한국지반공학회 논문집 | H15: Journal of the Korean Geotechnical Society | I15: =INDEX(학술지정보!$C$9:$O$50,MATCH($H15,학술지정보!$C$9:$C$50,0),2) -> 비SCI | J15: {=INDEX(학술지정보!$C$9:$O$50,MATCH($H15,학술지정보!$C$9:$C$50,0),3)} -> 1229-2427 | K15: {=IF(INDEX(학술지정보!$C$9:$O$50,MATCH($H15,학술지정보!$C$9:$C$50,0),5)=0,"",INDEX(학술지정보!$C$9:$O$50,MATCH($H15,학술지정보!$C$9:$C$50,0),5))} -> 2288-646X | AB15: =COUNTA(S15:AA15) -> 0
B16: =B15+1 -> 7 | C16: 2008 | D16: 1 | E16: 이축압축 조건에서 실험체/재하판 경계면상의 마찰저항 감소를 위한 롤러 지지된 피스톤 형태의 하중재하판의 개발 | F16: Development of a roller supported piston type loading platen reducing the frictional restraint along the interfaces between the specimen and platens under the biaxial loading condition | G16: 한국터널지하공간학회 논문집 | H16: Journal of Korean Tunnelling and Underground Space Association | I16: =INDEX(학술지정보!$C$9:$O$50,MATCH($H16,학술지정보!$C$9:$C$50,0),2) -> 비SCI | J16: {=INDEX(학술지정보!$C$9:$O$50,MATCH($H16,학술지정보!$C$9:$C$50,0),3)} -> 2233-8292 | K16: {=IF(INDEX(학술지정보!$C$9:$O$50,MATCH($H16,학술지정보!$C$9:$C$50,0),5)=0,"",INDEX(학술지정보!$C$9:$O$50,MATCH($H16,학술지정보!$C$9:$C$50,0),5))} -> 2287-4747 | AB16: =COUNTA(S16:AA16) -> 0
B17: =B16+1 -> 8 | C17: 2008 | D17: 2 | E17: 주파수 의존성을 고려한 등가선형해석기법의 검증 | F17: Verification of Frequency-dependent equivalent linear method | G17: 한국지반공학회 논문집 | H17: Journal of the Korean Geotechnical Society | I17: =INDEX(학술지정보!$C$9:$O$50,MATCH($H17,학술지정보!$C$9:$C$50,0),2) -> 비SCI | J17: {=INDEX(학술지정보!$C$9:$O$50,MATCH($H17,학술지정보!$C$9:$C$50,0),3)} -> 1229-2427 | K17: {=IF(INDEX(학술지정보!$C$9:$O$50,MATCH($H17,학술지정보!$C$9:$C$50,0),5)=0,"",INDEX(학술지정보!$C$9:$O$50,MATCH($H17,학술지정보!$C$9:$C$50,0),5))} -> 2288-646X | AB17: =COUNTA(S17:AA17) -> 0
B18: =B17+1 -> 9 | C18: 2008 | D18: 3 | E18: 한국 토양 프로파일의 비선형 지반 효과 평가 | F18: Estimation of nonlinear site effects of soil profiles in Korea | G18: 한국지반공학회 논문집 | H18: Journal of the Korean Geotechnical Society | I18: =INDEX(학술지정보!$C$9:$O$50,MATCH($H18,학술지정보!$C$9:$C$50,0),2) -> 비SCI | J18: {=INDEX(학술지정보!$C$9:$O$50,MATCH($H18,학술지정보!$C$9:$C$50,0),3)} -> 1229-2427 | K18: {=IF(INDEX(학술지정보!$C$9:$O$50,MATCH($H18,학술지정보!$C$9:$C$50,0),5)=0,"",INDEX(학술지정보!$C$9:$O$50,MATCH($H18,학술지정보!$C$9:$C$50,0),5))} -> 2288-646X | AB18: =COUNTA(S18:AA18) -> 0
B19: =B18+1 -> 10 | C19: 2008 | D19: 4 | E19: 공간적으로 변화하는 지반 운동에 따른 터널 응답 예측 | F19: Prediction of Tunnel Response by Spatially Variable Ground Motion | G19: 한국지반환경공학회 논문집 | H19: Journal of the Korean Geoenvironmental Society | I19: =INDEX(학술지정보!$C$9:$O$50,MATCH($H19,학술지정보!$C$9:$C$50,0),2) -> 비SCI | J19: {=INDEX(학술지정보!$C$9:$O$50,MATCH($H19,학술지정보!$C$9:$C$50,0),3)} -> 1598-0820 | K19: {=IF(INDEX(학술지정보!$C$9:$O$50,MATCH($H19,학술지정보!$C$9:$C$50,0),5)=0,"",INDEX(학술지정보!$C$9:$O$50,MATCH($H19,학술지정보!$C$9:$C$50,0),5))} | AB19: =COUNTA(S19:AA19) -> 0
B20: =B19+1 -> 11 | C20: 2009 | D20: 1 | E20: 국내 확률론적 지진계수 개발 | F20: Development of Probabilistic Seismic Coefficients of Korea | G20: 한국지반공학회 논문집 | H20: Journal of the Korean Geotechnical Society | I20: =INDEX(학술지정보!$C$9:$O$50,MATCH($H20,학술지정보!$C$9:$C$50,0),2) -> 비SCI | J20: {=INDEX(학술지정보!$C$9:$O$50,MATCH($H20,학술지정보!$C$9:$C$50,0),3)} -> 1229-2427 | K20: {=IF(INDEX(학술지정보!$C$9:$O$50,MATCH($H20,학술지정보!$C$9:$C$50,0),5)=0,"",INDEX(학술지정보!$C$9:$O$50,MATCH($H20,학술지정보!$C$9:$C$50,0),5))} -> 2288-646X | AB20: =COUNTA(S20:AA20) -> 0
B21: =B20+1 -> 12 | C21: 2009 | D21: 2 | E21: 신 유사정적 사면안정해석 기법 개발 | F21: Development of Novel Method of Seismic Slope Stability Analysis | G21: 한국지반환경공학회 논문집 | H21: Journal of the Korean Geoenvironmental Society
B22: =B21+1 -> 13 | C22: 2009 | D22: 3 | E22: 이축압축 조건에서 공동이 존재하는 유사 절리암반 모델의 파괴 거동 | F22: Fracture Behaviors of Jointed Rock Model Containing an Opening Under Biaxial Compression Condition | G22: 한국지반공학회 논문집 | H22: Journal of the Korean Geotechnical Society | I22: =INDEX(학술지정보!$C$9:$O$50,MATCH($H22,학술지정보!$C$9:$C$50,0),2) -> 비SCI | J22: {=INDEX(학술지정보!$C$9:$O$50,MATCH($H22,학술지정보!$C$9:$C$50,0),3)} -> 1229-2427 | K22: {=IF(INDEX(학술지정보!$C$9:$O$50,MATCH($H22,학술지정보!$C$9:$C$50,0),5)=0,"",INDEX(학술지정보!$C$9:$O$50,MATCH($H22,학술지정보!$C$9:$C$50,0),5))} -> 2288-646X | AB22: =COUNTA(S22:AA22) -> 0
B23: =B22+1 -> 14 | C23: 2009 | D23: 4 | E23: 신(新) 확률론적 지진재해분석 및 국내 지진계수 개발 Part I: 신(新) 확률론적 지진재해분석 기법 적용 및 검증 | F23: Development of New Probabilistic Seismic Hazard Analysis and Seismic Coefficients of Korea Part I: Application and Verification of a Novel Probabilistic Seismic Hazard Analysis Procedure | G23: 한국지반환경공학회 논문집 | H23: Journal of the Korean Geoenvironmental Society | I23: =INDEX(학술지정보!$C$9:$O$50,MATCH($H23,학술지정보!$C$9:$C$50,0),2) -> 비SCI | J23: {=INDEX(학술지정보!$C$9:$O$50,MATCH($H23,학술지정보!$C$9:$C$50,0),3)} -> 1598-0820 | K23: {=IF(INDEX(학술지정보!$C$9:$O$50,MATCH($H23,학술지정보!$C$9:$C$50,0),5)=0,"",INDEX(학술지정보!$C$9:$O$50,MATCH($H23,학술지정보!$C$9:$C$50,0),5))} | AB23: =COUNTA(S23:AA23) -> 0
B24: =B23+1 -> 15 | C24: 2009 | D24: 5 | E24: 한국의 새로운 확률론적 지진 위해도 해석 및 지진 계수 개발 II: 확률론적 지반 계수 도출 | F24: Development of New Probabilistic Seismic Hazard Analysis and Seismic Coefficients of Korea Part II: Derivation of Probabilistic Site Coefficients | G24: 한국지반환경공학회 논문집 | H24: Journal of the Korean Geoenvironmental Society | I24: =INDEX(학술지정보!$C$9:$O$50,MATCH($H24,학술지정보!$C$9:$C$50,0),2) -> 비SCI | J24: {=INDEX(학술지정보!$C$9:$O$50,MATCH($H24,학술지정보!$C$9:$C$50,0),3)} -> 1598-0820 | K24: {=IF(INDEX(학술지정보!$C$9:$O$50,MATCH($H24,학술지정보!$C$9:$C$50,0),5)=0,"",INDEX(학술지정보!$C$9:$O$50,MATCH($H24,학술지정보!$C$9:$C$50,0),5))} | AB24: =COUNTA(S24:AA24) -> 0
B25: =B24+1 -> 16 | C25: 2009 | D25: 6 | E25: 간소화된 방법과 유효 응력 지반 응답 해석을 이용한 액상화 가능성 평가 | F25: Evaluation of liquefaction potential with simplified method and effective-stress site response analysis | G25: 한국지반공학회 논문집 | H25: Journal of the Korean Geotechnical Society | I25: =INDEX(학술지정보!$C$9:$O$50,MATCH($H25,학술지정보!$C$9:$C$50,0),2) -> 비SCI | J25: {=INDEX(학술지정보!$C$9:$O$50,MATCH($H25,학술지정보!$C$9:$C$50,0),3)} -> 1229-2427 | K25: {=IF(INDEX(학술지정보!$C$9:$O$50,MATCH($H25,학술지정보!$C$9:$C$50,0),5)=0,"",INDEX(학술지정보!$C$9:$O$50,MATCH($H25,학술지정보!$C$9:$C$50,0),5))} -> 2288-646X | AB25: =COUNTA(S25:AA25) -> 0
B26: =B25+1 -> 17 | C26: 2010 | D26: 1 | E26: 터널의 횡방향 지진 해석 II: 동적 해석을 통한 지진 터널 응답 평가 | F26: Seismic analysis of tunnel in transverse direction part II: Evaluation of seismic tunnel response via dynamic analysis | G26: 한국지반공학회 논문집 | H26: Journal of the Korean Geotechnical Society | I26: =INDEX(학술지정보!$C$9:$O$50,MATCH($H26,학술지정보!$C$9:$C$50,0),2) -> 비SCI | J26: {=INDEX(학술지정보!$C$9:$O$50,MATCH($H26,학술지정보!$C$9:$C$50,0),3)} -> 1229-2427 | K26: {=IF(INDEX(학술지정보!$C$9:$O$50,MATCH($H26,학술지정보!$C$9:$C$50,0),5)=0,"",INDEX(학술지정보!$C$9:$O$50,MATCH($H26,학술지정보!$C$9:$C$50,0),5))} -> 2288-646X | AB26: =COUNTA(S26:AA26) -> 0
B27: =B26+1 -> 18 | C27: 2010 | D27: 2 | E27: 터널의 횡방향 지진 해석 I: 지진 변위를 이용한 터널 응답 추정 | F27: Seismic analysis of tunnel in transverse direction part I: Estimation of seismic tunnel response via method of seismic displacement | G27: 한국지반공학회 논문집 | H27: Journal of the Korean Geotechnical Society | I27: =INDEX(학술지정보!$C$9:$O$50,MATCH($H27,학술지정보!$C$9:$C$50,0),2) -> 비SCI | J27: {=INDEX(학술지정보!$C$9:$O$50,MATCH($H27,학술지정보!$C$9:$C$50,0),3)} -> 1229-2427 | K27: {=IF(INDEX(학술지정보!$C$9:$O$50,MATCH($H27,학술지정보!$C$9:$C$50,0),5)=0,"",INDEX(학술지정보!$C$9:$O$50,MATCH($H27,학술지정보!$C$9:$C$50,0),5))} -> 2288-646X | AB27: =COUNTA(S27:AA27) -> 0
B28: =B27+1 -> 19 | C28: 2010 | D28: 3 | E28: 스탠딩 칼럼 웰 지열 히트 펌프 시스템의 수치 시뮬레이션 II: 스탠딩 칼럼 웰 성능 평가를 위한 매개변수 연구 | F28: Numerical Simulation of Standing Column Well Ground Heat Pump System Part II: Parametric Study for Evaluation of the Performance of Standing Column Well | G28: 한국지반공학회 논문집 | H28: Journal of the Korean Geotechnical Society | I28: =INDEX(학술지정보!$C$9:$O$50,MATCH($H28,학술지정보!$C$9:$C$50,0),2) -> 비SCI | J28: {=INDEX(학술지정보!$C$9:$O$50,MATCH($H28,학술지정보!$C$9:$C$50,0),3)} -> 1229-2427 | K28: {=IF(INDEX(학술지정보!$C$9:$O$50,MATCH($H28,학술지정보!$C$9:$C$50,0),5)=0,"",INDEX(학술지정보!$C$9:$O$50,MATCH($H28,학술지정보!$C$9:$C$50,0),5))} -> 2288-646X | AB28: =COUNTA(S28:AA28) -> 0
B29: =B28+1 -> 20 | C29: 2010 | D29: 4 | E29: 스탠딩 칼럼 웰 지열 히트 펌프 시스템의 수치 시뮬레이션 I: 수치 모델 검증 | F29: Numerical Simulation of Standing Column Well Ground Heat Pump System Part 1: Validation of the Numerical Model | G29: 한국지반공학회 논문집 | H29: Journal of the Korean Geotechnical Society | I29: =INDEX(학술지정보!$C$9:$O$50,MATCH($H29,학술지정보!$C$9:$C$50,0),2) -> 비SCI | J29: {=INDEX(학술지정보!$C$9:$O$50,MATCH($H29,학술지정보!$C$9:$C$50,0),3)} -> 1229-2427 | K29: {=IF(INDEX(학술지정보!$C$9:$O$50,MATCH($H29,학술지정보!$C$9:$C$50,0),5)=0,"",INDEX(학술지정보!$C$9:$O$50,MATCH($H29,학술지정보!$C$9:$C$50,0),5))} -> 2288-646X | AB29: =COUNTA(S29:AA29) -> 0
B30: =B29+1 -> 21 | C30: 2010 | D30: 5 | E30: 수정된 등가 선형법의 정확성 평가 | F30: Evaluation of Accuracy of Modified Equivalent Linear Method | G30: 한국지반환경공학회 논문집 | H30: Journal of the Korean Geoenvironmental Society | I30: =INDEX(학술지정보!$C$9:$O$50,MATCH($H30,학술지정보!$C$9:$C$50,0),2) -> 비SCI | J30: {=INDEX(학술지정보!$C$9:$O$50,MATCH($H30,학술지정보!$C$9:$C$50,0),3)} -> 1598-0820 | K30: {=IF(INDEX(학술지정보!$C$9:$O$50,MATCH($H30,학술지정보!$C$9:$C$50,0),5)=0,"",INDEX(학술지정보!$C$9:$O$50,MATCH($H30,학술지정보!$C$9:$C$50,0),5))} | AB30: =COUNTA(S30:AA30) -> 0
B31: =B30+1 -> 22 | C31: 2011 | D31: 1 | E31: 대단면 터널에서 표준 지보 패턴의 평가: 수치 해석 및 현장 측정을 기반으로 | F31: Evaluation of the Standard Support Pattern in Large Section Tunnel by Numerical Analysis and Field Measurement | G31: 한국지반환경공학회 논문집 | H31: Journal of the Korean Geoenvironmental Society | I31: =INDEX(학술지정보!$C$9:$O$50,MATCH($H31,학술지정보!$C$9:$C$50,0),2) -> 비SCI | J31: {=INDEX(학술지정보!$C$9:$O$50,MATCH($H31,학술지정보!$C$9:$C$50,0),3)} -> 1598-0820 | K31: {=IF(INDEX(학술지정보!$C$9:$O$50,MATCH($H31,학술지정보!$C$9:$C$50,0),5)=0,"",INDEX(학술지정보!$C$9:$O$50,MATCH($H31,학술지정보!$C$9:$C$50,0),5))} | AB31: =COUNTA(S31:AA31) -> 0
B32: =B31+1 -> 23 | C32: 2011 | D32: 2 | E32: 터널 공사에서 제어 발파 공법과 폭약의 진동 전파 특성에 대한 연구 | F32: A study on the vibration propagation characteristics of controlled blasting methods and explosives in tunnelling | G32: 한국지반환경공학회 논문집 | H32: Journal of the Korean Geoenvironmental Society | I32: =INDEX(학술지정보!$C$9:$O$50,MATCH($H32,학술지정보!$C$9:$C$50,0),2) -> 비SCI | J32: {=INDEX(학술지정보!$C$9:$O$50,MATCH($H32,학술지정보!$C$9:$C$50,0),3)} -> 1598-0820 | K32: {=IF(INDEX(학술지정보!$C$9:$O$50,MATCH($H32,학술지정보!$C$9:$C$50,0),5)=0,"",INDEX(학술지정보!$C$9:$O$50,MATCH($H32,학술지정보!$C$9:$C$50,0),5))} | AB32: =COUNTA(S32:AA32) -> 0
B33: =B32+1 -> 24 | C33: 2011 | D33: 3 | E33: 목표 응답 스펙트럼에 맞춘 지반 운동 수정용 임펄스 함수 기반 알고리즘의 적용 가능성 평가 | F33: Evaluation of applicability of impulse function-based algorithm for modification of ground motion to match target response spectrum | G33: 한국지반환경공학회 논문집 | H33: Journal of the Korean Geoenvironmental Society | I33: =INDEX(학술지정보!$C$9:$O$50,MATCH($H33,학술지정보!$C$9:$C$50,0),2) -> 비SCI | J33: {=INDEX(학술지정보!$C$9:$O$50,MATCH($H33,학술지정보!$C$9:$C$50,0),3)} -> 1598-0820 | K33: {=IF(INDEX(학술지정보!$C$9:$O$50,MATCH($H33,학술지정보!$C$9:$C$50,0),5)=0,"",INDEX(학술지정보!$C$9:$O$50,MATCH($H33,학술지정보!$C$9:$C$50,0),5))} | AB33: =COUNTA(S33:AA33) -> 0
B34: =B33+1 -> 25 | C34: 2011 | D34: 4 | E34: 소형 FWD와 반복평판재하시험에서의 변형계수(Ev2)와의 상관관계 평가 | F34: Evaluation of correlation between Strain mudulus (Ev2) and Deformation modulus (ELFWD) Using Cyclic Plate loading Test and LFWD | G34: 한국토목섬유학회 논문집 | H34: Journal of the Korean Geosynthetics Society | I34: =INDEX(학술지정보!$C$9:$O$50,MATCH($H34,학술지정보!$C$9:$C$50,0),2) -> #N/A | J34: {=INDEX(학술지정보!$C$9:$O$50,MATCH($H34,학술지정보!$C$9:$C$50,0),3)} -> #N/A | K34: {=IF(INDEX(학술지정보!$C$9:$O$50,MATCH($H34,학술지정보!$C$9:$C$50,0),5)=0,"",INDEX(학술지정보!$C$9:$O$50,MATCH($H34,학술지정보!$C$9:$C$50,0),5))} -> #N/A
B35: =B34+1 -> 26 | C35: 2012 | D35: 1 | E35: 간극 수압 모델 기반 응력 개발 | F35: Development of Stress Based on Pore Pressure Model | G35: 한국지반공학회 논문집 | H35: Journal of the Korean Geotechnical Society | I35: =INDEX(학술지정보!$C$9:$O$50,MATCH($H35,학술지정보!$C$9:$C$50,0),2) -> 비SCI | J35: {=INDEX(학술지정보!$C$9:$O$50,MATCH($H35,학술지정보!$C$9:$C$50,0),3)} -> 1229-2427 | K35: {=IF(INDEX(학술지정보!$C$9:$O$50,MATCH($H35,학술지정보!$C$9:$C$50,0),5)=0,"",INDEX(학술지정보!$C$9:$O$50,MATCH($H35,학술지정보!$C$9:$C$50,0),5))} -> 2288-646X | AB35: =COUNTA(S35:AA35) -> 0
B36: =B35+1 -> 27 | C36: 2013 | D36: 1 | E36: 점토질 사질토의 투수성과 압밀 특성 | F36: Permeability and consolidation characteristics of clayey sand soils | G36: 한국지반공학회 논문집 | H36: Journal of the Korean Geotechnical Society | I36: =INDEX(학술지정보!$C$9:$O$50,MATCH($H36,학술지정보!$C$9:$C$50,0),2) -> 비SCI | J36: {=INDEX(학술지정보!$C$9:$O$50,MATCH($H36,학술지정보!$C$9:$C$50,0),3)} -> 1229-2427 | K36: {=IF(INDEX(학술지정보!$C$9:$O$50,MATCH($H36,학술지정보!$C$9:$C$50,0),5)=0,"",INDEX(학술지정보!$C$9:$O$50,MATCH($H36,학술지정보!$C$9:$C$50,0),5))} -> 2288-646X | AB36: =COUNTA(S36:AA36) -> 0
B37: =B36+1 -> 28 | C37: 2013 | D37: 2 | E37: 운영 중인 도로 터널의 내진 성능 평가 | F37: Evaluation of seismic performance of road tunnels in operation | G37: 한국터널지하공간학회 논문집 | H37: Journal of Korean Tunnelling and Underground Space Association | I37: =INDEX(학술지정보!$C$9:$O$50,MATCH($H37,학술지정보!$C$9:$C$50,0),2) -> 비SCI | J37: {=INDEX(학술지정보!$C$9:$O$50,MATCH($H37,학술지정보!$C$9:$C$50,0),3)} -> 2233-8292 | K37: {=IF(INDEX(학술지정보!$C$9:$O$50,MATCH($H37,학술지정보!$C$9:$C$50,0),5)=0,"",INDEX(학술지정보!$C$9:$O$50,MATCH($H37,학술지정보!$C$9:$C$50,0),5))} -> 2287-4747 | AB37: =COUNTA(S37:AA37) -> 0
B38: =B37+1 -> 29 | C38: 2013 | D38: 3 | E38: 산사면의 증폭 특성 | F38: Amplification characteristics of mountain slopes | G38: 한국방재학회 | H38: Journal of the Korean Society of Hazard Mitigation | I38: =INDEX(학술지정보!$C$9:$O$50,MATCH($H38,학술지정보!$C$9:$C$50,0),2) -> 비SCI | J38: {=INDEX(학술지정보!$C$9:$O$50,MATCH($H38,학술지정보!$C$9:$C$50,0),3)} -> 1738-2424 | K38: {=IF(INDEX(학술지정보!$C$9:$O$50,MATCH($H38,학술지정보!$C$9:$C$50,0),5)=0,"",INDEX(학술지정보!$C$9:$O$50,MATCH($H38,학술지정보!$C$9:$C$50,0),5))} -> 2287-6723 | AB38: =COUNTA(S38:AA38) -> 0
B39: =B38+1 -> 30 | C39: 2014 | D39: 1 | E39: 탄성파를 통한 시료성형방법에 따른 모래 전단거동특성 평가 | F39: Evaluation of the Influence of the Method of Sample Preparation on the Shearing Behavior of Sands using Elastic Waves | G39: 한국지반환경공학회 논문집 | H39: Journal of the Korean Geoenvironmental Society | I39: =INDEX(학술지정보!$C$9:$O$50,MATCH($H39,학술지정보!$C$9:$C$50,0),2) -> 비SCI | J39: {=INDEX(학술지정보!$C$9:$O$50,MATCH($H39,학술지정보!$C$9:$C$50,0),3)} -> 1598-0820 | K39: {=IF(INDEX(학술지정보!$C$9:$O$50,MATCH($H39,학술지정보!$C$9:$C$50,0),5)=0,"",INDEX(학술지정보!$C$9:$O$50,MATCH($H39,학술지정보!$C$9:$C$50,0),5))} | AB39: =COUNTA(S39:AA39) -> 0
B40: =B39+1 -> 31 | C40: 2014 | D40: 2 | E40: 도로구조물의 발파진동 허용기준에 관한 연구 | F40: Study on the Allowable Limit of Blasting-induced Vibration for Road Structures and Facilities | G40: 한국지반공학회 논문집 | H40: Journal of the Korean Geotechnical Society | I40: =INDEX(학술지정보!$C$9:$O$50,MATCH($H40,학술지정보!$C$9:$C$50,0),2) -> 비SCI | J40: {=INDEX(학술지정보!$C$9:$O$50,MATCH($H40,학술지정보!$C$9:$C$50,0),3)} -> 1229-2427 | K40: {=IF(INDEX(학술지정보!$C$9:$O$50,MATCH($H40,학술지정보!$C$9:$C$50,0),5)=0,"",INDEX(학술지정보!$C$9:$O$50,MATCH($H40,학술지정보!$C$9:$C$50,0),5))} -> 2288-646X | AB40: =COUNTA(S40:AA40) -> 0
B41: =B40+1 -> 32 | C41: 2014 | D41: 3 | E41: 기존 고속철도 터널의 지진취약도 함수 개발에 관한 연구 | F41: A study on the development of the seismic fragility functions of the high speed railway tunnels in use | G41: 한국지반환경공학회 논문집 | H41: Journal of the Korean Geoenvironmental Society | I41: =INDEX(학술지정보!$C$9:$O$50,MATCH($H41,학술지정보!$C$9:$C$50,0),2) -> 비SCI | J41: {=INDEX(학술지정보!$C$9:$O$50,MATCH($H41,학술지정보!$C$9:$C$50,0),3)} -> 1598-0820 | K41: {=IF(INDEX(학술지정보!$C$9:$O$50,MATCH($H41,학술지정보!$C$9:$C$50,0),5)=0,"",INDEX(학술지정보!$C$9:$O$50,MATCH($H41,학술지정보!$C$9:$C$50,0),5))} | AB41: =COUNTA(S41:AA41) -> 0
B42: =B41+1 -> 33 | C42: 2014 | D42: 4 | E42: 벤더엘리먼트와 삼축시험을 통한 모래의 전단강도 및 포아송비 특성 규명 | F42: Evaluation of Characteristics of Shear Strength and Poisso’s Ratio through Triaxial and Bender Element Tests | G42: 한국지반공학회 논문집 | H42: Journal of the Korean Geotechnical Society | I42: =INDEX(학술지정보!$C$9:$O$50,MATCH($H42,학술지정보!$C$9:$C$50,0),2) -> 비SCI | J42: {=INDEX(학술지정보!$C$9:$O$50,MATCH($H42,학술지정보!$C$9:$C$50,0),3)} -> 1229-2427 | K42: {=IF(INDEX(학술지정보!$C$9:$O$50,MATCH($H42,학술지정보!$C$9:$C$50,0),5)=0,"",INDEX(학술지정보!$C$9:$O$50,MATCH($H42,학술지정보!$C$9:$C$50,0),5))} -> 2288-646X | AB42: =COUNTA(S42:AA42) -> 0
B43: =B42+1 -> 34 | C43: 2014 | D43: 5 | E43: 동시베리아 지역의 지진 증폭 특성 | F43: Seismic amplification characteristics of Eastern Siberia | G43: 한국지반공학회 논문집 | H43: Journal of the Korean Geotechnical Society | I43: =INDEX(학술지정보!$C$9:$O$50,MATCH($H43,학술지정보!$C$9:$C$50,0),2) -> 비SCI | J43: {=INDEX(학술지정보!$C$9:$O$50,MATCH($H43,학술지정보!$C$9:$C$50,0),3)} -> 1229-2427 | K43: {=IF(INDEX(학술지정보!$C$9:$O$50,MATCH($H43,학술지정보!$C$9:$C$50,0),5)=0,"",INDEX(학술지정보!$C$9:$O$50,MATCH($H43,학술지정보!$C$9:$C$50,0),5))} -> 2288-646X | AB43: =COUNTA(S43:AA43) -> 0
B44: =B43+1 -> 35 | C44: 2014 | D44: 6 | E44: 터널의 지진응답에 대한 암반 절리의 영향 평가 | F44: Evaluation of Effect of Rock Joints on Seismic Response of Tunnels | G44: 한국지반공학회 논문집 | H44: Journal of the Korean Geotechnical Society | I44: =INDEX(학술지정보!$C$9:$O$50,MATCH($H44,학술지정보!$C$9:$C$50,0),2) -> 비SCI | J44: {=INDEX(학술지정보!$C$9:$O$50,MATCH($H44,학술지정보!$C$9:$C$50,0),3)} -> 1229-2427 | K44: {=IF(INDEX(학술지정보!$C$9:$O$50,MATCH($H44,학술지정보!$C$9:$C$50,0),5)=0,"",INDEX(학술지정보!$C$9:$O$50,MATCH($H44,학술지정보!$C$9:$C$50,0),5))} -> 2288-646X | AB44: =COUNTA(S44:AA44) -> 0
B45: =B44+1 -> 36 | C45: 2014 | D45: 7 | E45: 터널 굴착 발파하중 시간이력 생성 | F45: Generation of blast load time series under tunnelling | G45: 한국터널지하공간학회 논문집 | H45: Journal of Korean Tunnelling and Underground Space Association | I45: =INDEX(학술지정보!$C$9:$O$50,MATCH($H45,학술지정보!$C$9:$C$50,0),2) -> 비SCI | J45: {=INDEX(학술지정보!$C$9:$O$50,MATCH($H45,학술지정보!$C$9:$C$50,0),3)} -> 2233-8292 | K45: {=IF(INDEX(학술지정보!$C$9:$O$50,MATCH($H45,학술지정보!$C$9:$C$50,0),5)=0,"",INDEX(학술지정보!$C$9:$O$50,MATCH($H45,학술지정보!$C$9:$C$50,0),5))} -> 2287-4747 | AB45: =COUNTA(S45:AA45) -> 0
...

Sheet 국외학술발표 (2000~2024)
B2: 번호 | C2: 연도 | D2: 논문제목 | E2: 게재논문집명(영어)
B3: 1 | C3: 2000 | D3: Non-linear site response analysis for deep deposits in New Madrid Seismic Zone | E3: 4th International Conference on Recent Advances in Geotechnical Earthquake Engineering and Soil Dynamics
B4: =B3+1 -> 2 | C4: 2002 | D4: Seismic site response of deep soil deposits and relationship to response of longitudinal structures | E4: 4th US-Japan-China Symposium on Lifeline Earthquake Engineering
B5: =B4+1 -> 3 | C5: 2002 | D5: Site response analysis in the Mississippi Embayment | E5: US-Japan seminar on seismic disaster mitigation in urban area by geotechnical engineering
B6: =B5+1 -> 4 | C6: 2002 | D6: Site response analysis of deep deposits | E6: 7th National Conference on Earthquake Engineering
B7: =B6+1 -> 5 | C7: 2004 | D7: Probabilistic seismic hazard analysis with nonlinear site effects in the Mississippi Embayment | E7: 13th World Conference on Earthquake Engineering, Vancouver
B8: =B7+1 -> 6 | C8: 2004 | D8: Nonlinear seismic site response of deep deposits in West Tennessee | E8: 4th Seismic Conference and Workshop on Bridges and Highways
B9: =B8+1 -> 7 | C9: 2004 | D9: Estimation of small damping properties in the Mississippi Embayment | E9: 11th International Conference on Soil Dynamics & Earthquake Engineering & 3rd International Conference on Earthquake Geotechnical Engineering, Berkeley, CA
B10: =B9+1 -> 8 | C10: 2007 | D10: Nonlinear site response analysis in deep soft clay deposits in Korea | E10: 13th Asian Regional Conference on Soil Mechanics and Geotechnical Engineering, Kolkata, India
B11: =B10+1 -> 9 | C11: 2007 | D11: Generation of spatially variable ground motions for seismic analysis of undersea tunnel | E11: Chinese Journal of Rock Mechanics and Engineering
B12: =B11+1 -> 10 | C12: 2007 | D12: Generation of spatially variable ground motions for seismic analysis of undersea tunnel | E12: 13th World Conference on Earthquake Engineering, Vancouver
B13: =B12+1 -> 11 | C13: 2007 | D13: Development of a New Equivalent Linear Algorithm with Rate Dependent Soil Model | E13: 17th International Offshore and Polar Engineering Conference, Lisbon
B14: =B13+1 -> 12 | C14: 2007 | D14: Seismic Site Effects for Weak Deposits in Korea | E14: 17th International Offshore and Polar Engineering Conference, Lisbon
B15: =B14+1 -> 13 | C15: 2007 | D15: Development of Representative Ground Motions for Seismic Analysis of Nuclear Plants in Korea | E15: 19th International Conference on Structural Mechanics in Reactor Technology, Toronto, Ontario, Canada
... B52: =B51+1 -> 50 | C52: 2024 | D52: Machine learning based site amplification prediction models for shallow bedrock sites | E52: The 8th International Conference on Earthquake Geotechnical Engineering, Osaka, Japan
